#VRML_SIM R2023b utf8

EXTERNPROTO "https://raw.githubusercontent.com/cyberbotics/webots/R2023b/projects/objects/backgrounds/protos/TexturedBackground.proto"
EXTERNPROTO "https://raw.githubusercontent.com/cyberbotics/webots/R2023b/projects/objects/backgrounds/protos/TexturedBackgroundLight.proto"
EXTERNPROTO "https://raw.githubusercontent.com/cyberbotics/webots/R2023b/projects/objects/floors/protos/Floor.proto"

WorldInfo {
  info [
    "Example world demonstrating the use of the Muscle node"
  ]
  title "Muscle"
  basicTimeStep 16
  gravity 9.81
}
Viewpoint {
  orientation -0.5223578251770465 0.09301806886713386 0.8476378597847877 2.7753819314893793
  position 0.26745501991810305 -0.05987278174127601 0.44031085296688044
}
TexturedBackground {
}
TexturedBackgroundLight {
}
Floor {
  size 5 5
}





DEF WORM Robot {
  translation 1 1 0.5
  children [
      DEF JOINT_0_0 Shape {
        appearance PBRAppearance {
          baseColor 0.337255 0.337255 0.337255
          roughness 1
          metalness 0
          transparency 0.009999999776482582
        }
        geometry Sphere {
          radius 0.008
        }
      }
      SliderJoint {
        jointParameters JointParameters {
          axis 0 1 0
        }
        device [
            LinearMotor {
              name "muscle_0_0"
              controlPID 0.4 0.6 0
              minPosition 0
              maxPosition 1
              maxForce 0.3
              muscles [
                  Muscle {
                    volume 0.0001
                    color [1 0 0 1 1 0 1 0 1]
                  }
                ]
            }
            PositionSensor {
              name "muscle_0_0_sensor"
            }
          ]
        endPoint Solid {
          translation 0 0.1 0.1732051
          children [
              DEF JOINT_0_1 Shape {
                appearance PBRAppearance {
                  baseColor 0.337255 0.337255 0.337255
                  roughness 1
                  metalness 0
                  transparency 0.009999999776482582
                }
                geometry Sphere {
                  radius 0.008
                }
              }
              SliderJoint {
                jointParameters JointParameters {
                  axis 0 1 0
                }
                device [
                    LinearMotor {
                      name "muscle_0_1"
                      controlPID 0.4 0.6 0
                      minPosition 0
                      maxPosition 1
                      maxForce 0.3
                      muscles [
                          Muscle {
                            volume 0.0001
                            color [1 0 0 1 1 0 1 0 1]
                          }
                        ]
                    }
                    PositionSensor {
                      name "muscle_0_1_sensor"
                    }
                  ]
                endPoint Solid {
                  translation 0 -0.1 0.1732051
                  children [
                      DEF JOINT_0_2 Shape {
                        appearance PBRAppearance {
                          baseColor 0.337255 0.337255 0.337255
                          roughness 1
                          metalness 0
                          transparency 0.009999999776482582
                        }
                        geometry Sphere {
                          radius 0.008
                        }
                      }
                      SliderJoint {
                        jointParameters JointParameters {
                          axis 0 1 0
                        }
                        device [
                            LinearMotor {
                              name "muscle_0_2"
                              controlPID 0.4 0.6 0
                              minPosition 0
                              maxPosition 1
                              maxForce 0.3
                              muscles [
                                  Muscle {
                                    volume 0.0001
                                    color [1 0 0 1 1 0 1 0 1]
                                  }
                                ]
                            }
                            PositionSensor {
                              name "muscle_0_2_sensor"
                            }
                          ]
                        endPoint Solid {
                          translation 0 -0.2 0.0
                          children [
                              DEF JOINT_0_3 Shape {
                                appearance PBRAppearance {
                                  baseColor 0.337255 0.337255 0.337255
                                  roughness 1
                                  metalness 0
                                  transparency 0.009999999776482582
                                }
                                geometry Sphere {
                                  radius 0.008
                                }
                              }
                              SliderJoint {
                                jointParameters JointParameters {
                                  axis 0 1 0
                                }
                                device [
                                    LinearMotor {
                                      name "muscle_0_3"
                                      controlPID 0.4 0.6 0
                                      minPosition 0
                                      maxPosition 1
                                      maxForce 0.3
                                      muscles [
                                          Muscle {
                                            volume 0.0001
                                            color [1 0 0 1 1 0 1 0 1]
                                          }
                                        ]
                                    }
                                    PositionSensor {
                                      name "muscle_0_3_sensor"
                                    }
                                  ]
                                endPoint Solid {
                                  translation 0 -0.1 -0.1732051
                                  children [
                                      DEF JOINT_0_4 Shape {
                                        appearance PBRAppearance {
                                          baseColor 0.337255 0.337255 0.337255
                                          roughness 1
                                          metalness 0
                                          transparency 0.009999999776482582
                                        }
                                        geometry Sphere {
                                          radius 0.008
                                        }
                                      }
                                      SliderJoint {
                                        jointParameters JointParameters {
                                          axis 0 1 0
                                        }
                                        device [
                                            LinearMotor {
                                              name "muscle_0_4"
                                              controlPID 0.4 0.6 0
                                              minPosition 0
                                              maxPosition 1
                                              maxForce 0.3
                                              muscles [
                                                  Muscle {
                                                    volume 0.0001
                                                    color [1 0 0 1 1 0 1 0 1]
                                                  }
                                                ]
                                            }
                                            PositionSensor {
                                              name "muscle_0_4_sensor"
                                            }
                                          ]
                                        endPoint Solid {
                                          translation 0 0.1 -0.1732051
                                          children [
                                              DEF JOINT_0_5 Shape {
                                                appearance PBRAppearance {
                                                  baseColor 0.337255 0.337255 0.337255
                                                  roughness 1
                                                  metalness 0
                                                  transparency 0.009999999776482582
                                                }
                                                geometry Sphere {
                                                  radius 0.008
                                                }
                                              }
                                            ]
                                          boundingObject USE JOINT_0_5
                                          physics Physics {
                                            density 1
                                            mass 2
                                          }
                                        }
                                      }
                                    ]
                                  boundingObject USE JOINT_0_4
                                  physics Physics {
                                    density 1
                                    mass 2
                                  }
                                }
                              }
                            ]
                          boundingObject USE JOINT_0_3
                          physics Physics {
                            density 1
                            mass 2
                          }
                        }
                      }
                    ]
                  boundingObject USE JOINT_0_2
                  physics Physics {
                    density 1
                    mass 2
                  }
                }
              }
            ]
          boundingObject USE JOINT_0_1
          physics Physics {
            density 1
            mass 2
          }
        }
      },
      SliderJoint {
                                                jointParameters JointParameters {
                                                  axis 0 1 0
                                                }
                                                device [
                                                    LinearMotor {
                                                      name "muscle_0_5"
                                                      controlPID 0.4 0.6 0
                                                      minPosition 0
                                                      maxPosition 1
                                                      maxForce 0.3
                                                      muscles [
                                                          Muscle {
                                                            volume 0.0001
                                                            color [1 0 0 1 1 0 1 0 1]
                                                          }
                                                        ]
                                                    }
                                                    PositionSensor {
                                                      name "muscle_0_5_sensor"
                                                    }
                                                  ]
                                                endPoint Solid {
                                                  translation 0 0.0 0.0
                                                  rotation 1 0 0 1.0472
                                                  children [
                                                      USE JOINT_0_0
                                                    ]
                                                  boundingObject USE JOINT_0_0
                                                  physics Physics {
                                                    density 1
                                                    mass 2
                                                  }
                                                }
                                              }
    ]
  name "worm"
  boundingObject USE JOINT_0_0
  physics Physics {
                                            density 1
                                            mass 2
                                          }
  controller "ring_muscle"
}
